Workbook

Sheet 1236  1260
A1: Fbaez | AL1: OBSERVACIONES | AM1: REFERENCIA
A2: G1 TM- 06a18HS | G2: 1 | H2: 2 | I2: 3 | J2: 4 | K2: 5 | L2: 6 | M2: 7 | N2: 8 | O2: 9 | P2: 10 | Q2: 11 | R2: 12 | S2: 13 | T2: 14 | U2: 15 | V2: 16 | W2: 17 | X2: 18 | Y2: 19 | Z2: 20 | AA2: 21 | AB2: 22 | AC2: 23 | AD2: 24 | AE2: 25 | AF2: 26 | AG2: 27 | AH2: 28 | AI2: 29 | AJ2: 30 | AK2: 31 | AM2: BLANCO | AN2: P
A3: JERARQUIA | B3: NOMBRE Y APELLIDO | C3: LP/DNI | D3: CELULAR | E3: FUNCION | F3: DOMICILIO | G3: S | H3: D | I3: L | J3: M | K3: M | L3: J | M3: V | N3: S | O3: D | P3: L | Q3: M | R3: M | S3: J | T3: V | U3: S | V3: D | W3: L | X3: M | Y3: M | Z3: J | AA3: V | AB3: S | AC3: D | AD3: L | AE3: M | AF3: M | AG3: J | AH3: V | AI3: S | AJ3: D | AK3: L | AM3: AMARILLO | AN3: FA
A4: JEFE DE SERVICIO | AM4: CELESTE | AN4: LM
A5: Inspector | B5: Aguirre, Alan | C5: 4532 | D5: 11-5619-5264 | E5: JEFE DE SERVICIO | F5: Almirante Brown 2484 dpto 2 - Moreno (PBA) | H5: P | J5: P | L5: P | P5: P | R5: P | T5: P | V5: P | X5: P | Z5: P | AD5: FA | AF5: P | AH5: P | AJ5: P | AM5: VERDE | AN5: LA
A6: OFICIALES DE LINEA | AM6: VERDE CLARO | AN6: LXUC
A7: Of. Mayor | B7: Meza, Gastón | C7: 3375 | D7: 11-4176-1568 | E7: OF 9DJ | F7: MENDOZA 1685 - FLORENCIO VARELA | H7: P | J7: P | L7: P | P7: P | R7: P | T7: P | V7: P | X7: LA | Y7: LA | Z7: LA | AA7: LA | AB7: LA | AC7: LA | AD7: LA | AE7: LA | AF7: LA | AG7: LA | AH7: LA | AI7: LA | AJ7: LA | AK7: LA | AL7: 46267 | AM7: GRIS | AN7: SAN
A8: Of. Mayor | B8: Tolaba, Adrian | C8: 6850 | D8: 1127544762 | E8: OF DE LINEA | F8: MIrave 3020 | H8: P | L8: P | N8: FAC | P8: LA | Q8: LA | R8: LA | S8: LA | T8: LA | U8: LA | V8: LA | W8: LA | X8: LA | Y8: LA | Z8: LA | AA8: PASA AL GRUPO 2 | AM8: AUSENTE | AN8: A
A9: Of. Mayor | B9: Rodríguez, Cristian | C9: 46641 | D9: 11-5869-7419 | E9: OF DE LINEA | F9: Turner 535 - Tristan Suarez | H9: P | J9: P | L9: P | P9: P | R9: P | T9: LM | U9: LM | V9: LM | X9: CG | Y9: P | Z9: P | AH9: CG | AI9: P | AJ9: P
A10: Of. Primero | B10: Pérez, Ramón | C10: 77827 | D10: 11-2756-0412 | E10: OF DE LINEA | F10: TORIBIO DE LUZURIAGA 2050-HURLINGAM- | G10: LA | H10: LA | I10: LA | J10: LA | K10: LA | L10: LA | M10: LA | N10: LA | P10: FA | R10: P | T10: P | V10: P | X10: P | Z10: P | AC10: - | AD10: P | AF10: P | AH10: P | AJ10: P | AM10: ROSA | AN10: LXM/LXP
A11: Of. Primero | B11: Rivero, Marcos | C11: 7025 | D11: 11-6930-2194 | E11: OFICIAL DE LÍNEA | F11: Tucuman 881 P.11 DPTO. 95- CABA | AJ11: P
A12: Oficial | B12: Vallejos, Catherine | C12: 59764 | D12: 11-6637-4311 | E12: AUX SISEP / SAE | F12: Santa Fe 124 Lomas | H12: P | J12: P | L12: P | P12: P | R12: P | V12: P | X12: P | Z12: FA | AD12: P | AF12: CG | AG12: P | AH12: P | AJ12: P | AM12: NARANJA | AN12: LxF
A13: Oficial | B13: Bravo Ayelén Antonela | C13: 59059 | D13: 11-5483-8847 | E13: OF DE LINEA | F13: El Benteveo 2597- Rafael Calzada | H13: FA | J13: P | L13: P | Q13: P | R13: P | T13: P | Z13: P | AD13: 5 | AH13: P | AJ13: FA | AM13: MORADO | AN13: FAC
A14: Oficial | B14: Crespin, Veronica | C14: 38107 | D14: 11-4093-5484 | E14: GAP | F14: Olaya 1049 4D - CABA | H14: CG | J14: LLT | L14: LM | O14: LLT | P14: LLT | R14: LLT | T14: LLT | V14: LLT | X14: LLT | Z14: LLT | AD14: P | AF14: LLT | AH14: LLT | AJ14: P
A15: Oficial | B15: Guzman, Yesica Mariel | C15: 29049 | D15: 11-3922-7578 | E15: OFICIAL DE LÍNEA | F15: SCHUBERT 1286- MERLO | H15: P | J15: P | K15: SAN | L15: SAN | M15: SAN | N15: SAN | O15: SAN | P15: P | R15: P | T15: P | V15: P | X15: P | Y15: P | Z15: FA | AA15: PASA A SECCION LUGANO GRUPO 2
A16: Oficial | B16: Portillo, Sergio Daniel | C16: 89190 | D16: 11-7020-9186 | E16: OF. DE LINEA | F16: Luis Viale 1286 Isidro Casanova | G16: P | AG16: p | AH16: P | AJ16: P
A17: Oficial | B17: Casas, Agustin Andres | C17: 89321 | D17: 11-2467-9780 | E17: OFI. DE LINEA | F17: HERNANDARIAS 3136 - Los Polvorines - PBA | H17: P | J17: P | L17: P | P17: LLT | R17: P | T17: P | V17: P | Y17: P | Z17: LLT | AB17: P
A18: AYUDANTES DE GUARDIA | AN18: Observaciones | AO18: LLT | AP18: LM | AQ18: FAC | AR18: LXE | AS18: LA
A19: Nivel G | B19: Ribeiro, Cecilia | C19: 32874 | D19: 11-3932-8150 | E19: SISEP | F19: Malabia 2231 - CABA | H19: LLT | J19: LLT | L19: P | P19: P | R19: P | T19: LA | U19: LA | V19: LA | W19: LA | X19: LA | Y19: LA | Z19: LA | AA19: LA | AB19: LA | AC19: LA | AD19: LA | AE19: LA | AF19: LA | AG19: LA | AH19: FA | AJ19: FA | AN19: =IFS(AO19>3,"NO CORRESPONDE FRANCO",AT19>0,"NO CORRESPONDE FRANCO",AT19=0,"") -> NO CORRESPONDE FRANCO | AO19: =COUNTIF($G19:$AK19,"LLT") -> 2 | AP19: =COUNTIF($G19:$AK19,"LM") -> 0 | AQ19: =COUNTIF($G19:$AK19,"FaC") -> 0 | AR19: =COUNTIF($G19:$AK19,"LxE") -> 0 | AS19: =COUNTIF($G19:$AK19,"LA") -> 14 | AT19: =SUM(AP19:AS19) -> 14
A20: Nivel G | B20: Rivera, Karen | C20: 34471 | D20: 11-3756-0313 / POC 11-3644-8070 | E20: SISEP | F20: BRAGADO 4863- DPTO 1- CABA | H20: P | J20: P | L20: P | P20: FA | R20: LLT | T20: P | V20: P | X20: P | Z20: P | AD20: P | AF20: P | AH20: P | AJ20: P | AN20: =IFS(AO20>3,"NO CORRESPONDE FRANCO",AT20>0,"NO CORRESPONDE FRANCO",AT20=0,"") | AO20: =COUNTIF($G20:$AK20,"LLT") -> 1 | AP20: =COUNTIF($G20:$AK20,"LM") -> 0 | AQ20: =COUNTIF($G20:$AK20,"FaC") -> 0 | AR20: =COUNTIF($G20:$AK20,"LxE") -> 0 | AS20: =COUNTIF($G20:$AK20,"LA") -> 0 | AT20: =SUM(AP20:AS20) -> 0
A21: Nivel I | B21: Garcia Nadia | C21: 70453 | D21: 11-6703-4212 | E21: ADM | F21: Reconquista 2741 - Merlo | H21: LLT | J21: P | L21: P | P21: P | R21: LLT | T21: P | V21: FA | X21: P | Z21: P | AD21: PASA AL GRUPO 2 | AN21: =IFS(AO21>3,"NO CORRESPONDE FRANCO",AT21>0,"NO CORRESPONDE FRANCO",AT21=0,"") | AO21: =COUNTIF($G21:$AK21,"LLT") -> 2 | AP21: =COUNTIF($G21:$AK21,"LM") -> 0 | AQ21: =COUNTIF($G21:$AK21,"FaC") -> 0 | AR21: =COUNTIF($G21:$AK21,"LxE") -> 0 | AS21: =COUNTIF($G21:$AK21,"LA") -> 0 | AT21: =SUM(AP21:AS21) -> 0
A22: Nivel J | B22: Barros Sergio Javier | C22: 13809 | D22: 11-4057-0789 | E22: ADM | F22: LUIS VIALE 269 CABA | H22: FA | J22: LLT | L22: P | P22: P | R22: P | T22: P | V22: LLT | X22: P | Z22: P | AB22: P | AD22: CG | AF22: P | AH22: P | AJ22: P | AN22: =IFS(AO22>3,"NO CORRESPONDE FRANCO",AT22>0,"NO CORRESPONDE FRANCO",AT22=0,"") | AO22: =COUNTIF($G22:$AK22,"LLT") -> 2 | AP22: =COUNTIF($G22:$AK22,"LM") -> 0 | AQ22: =COUNTIF($G22:$AK22,"FaC") -> 0 | AR22: =COUNTIF($G22:$AK22,"LxE") -> 0 | AS22: =COUNTIF($G22:$AK22,"LA") -> 0 | AT22: =SUM(AP22:AS22) -> 0
A23: Contratado | B23: Albrecht, Joel | C23: 41803371 | D23: 11-6501-2385 | E23: SISEP | F23: Castelli 1609, San Martín | H23: P | J23: P | L23: P | P23: P | R23: P | T23: P | V23: P | X23: P | Z23: FA | AD23: P | AF23: P | AH23: P | AJ23: P | AN23: =IFS(AO23>3,"NO CORRESPONDE FRANCO",AT23>0,"NO CORRESPONDE FRANCO",AT23=0,"") | AO23: =COUNTIF($G23:$AK23,"LLT") -> 0 | AP23: =COUNTIF($G23:$AK23,"LM") -> 0 | AQ23: =COUNTIF($G23:$AK23,"FaC") -> 0 | AR23: =COUNTIF($G23:$AK23,"LxE") -> 0 | AS23: =COUNTIF($G23:$AK23,"LA") -> 0 | AT23: =SUM(AP23:AS23) -> 0
A24: Contratado | B24: Vignolles, Macarena | C24: 45623522 | D24: 11-3623-9248 | E24: SAE | F24: Felipe Lavallol 2156- Grand Bourge | G24: LA | H24: LA | J24: P | L24: LM | P24: P | R24: P | T24: P | V24: LLT | X24: P | Z24: P | AD24: P | AF24: P | AH24: P | AJ24: LLT | AN24: =IFS(AO24>3,"NO CORRESPONDE FRANCO",AT24>0,"NO CORRESPONDE FRANCO",AT24=0,"") -> NO CORRESPONDE FRANCO | AO24: =COUNTIF($G24:$AK24,"LLT") -> 2 | AP24: =COUNTIF($G24:$AK24,"LM") -> 1 | AQ24: =COUNTIF($G24:$AK24,"FaC") -> 0 | AR24: =COUNTIF($G24:$AK24,"LxE") -> 0 | AS24: =COUNTIF($G24:$AK24,"LA") -> 2 | AT24: =SUM(AP24:AS24) -> 3
A25: Contratado | B25: Leivas, Ludmila | C25: 40006637 | D25: 11-6489-9807 | E25: ADM | F25: Andres Ferreira 4262 Dpto B - Caseros | H25: LLT | J25: LLT | L25: P | P25: P | R25: P | T25: LLT | V25: LLT | X25: P | Z25: P | AD25: P | AF25: P | AH25: P | AJ25: FA | AN25: =IFS(AO25>3,"NO CORRESPONDE FRANCO",AT25>0,"NO CORRESPONDE FRANCO",AT25=0,"") -> NO CORRESPONDE FRANCO | AO25: =COUNTIF($G25:$AK25,"LLT") -> 4 | AP25: =COUNTIF($G25:$AK25,"LM") -> 0 | AQ25: =COUNTIF($G25:$AK25,"FaC") -> 0 | AR25: =COUNTIF($G25:$AK25,"LxE") -> 0 | AS25: =COUNTIF($G25:$AK25,"LA") -> 0 | AT25: =SUM(AP25:AS25) -> 0
A26: Contratado | B26: Paz, Priscila | C26: 35979500 | D26: 11-3490-2633 | E26: ADM | F26: Dr. Belaustegui 4708 - Velez Sarsfield CABA | H26: FA | J26: P | L26: P | P26: P | R26: P | T26: P | V26: FA | X26: P | Y26: PASA AL DEPARTAMENTO.- | AN26: =IFS(AO26>3,"NO CORRESPONDE FRANCO",AT26>0,"NO CORRESPONDE FRANCO",AT26=0,"") | AO26: =COUNTIF($G26:$AK26,"LLT") -> 0 | AP26: =COUNTIF($G26:$AK26,"LM") -> 0 | AQ26: =COUNTIF($G26:$AK26,"FaC") -> 0 | AR26: =COUNTIF($G26:$AK26,"LxE") -> 0 | AS26: =COUNTIF($G26:$AK26,"LA") -> 0 | AT26: =SUM(AP26:AS26) -> 0
A27: Contratado | B27: Krakovsky, Florencia Abril | C27: 41290026 | D27: 11-6828-8168 | E27: SAE | F27: Venezuela y Posadas Sector J duplex 7 - Ezpeleta | H27: P | J27: P | L27: P | P27: P | R27: P | T27: P | V27: P | X27: FA | Z27: P | AD27: P | AF27: P | AH27: P | AJ27: P | AN27: =IFS(AO27>3,"NO CORRESPONDE FRANCO",AT27>0,"NO CORRESPONDE FRANCO",AT27=0,"") | AO27: =COUNTIF($G27:$AK27,"LLT") -> 0 | AP27: =COUNTIF($G27:$AK27,"LM") -> 0 | AQ27: =COUNTIF($G27:$AK27,"FaC") -> 0 | AR27: =COUNTIF($G27:$AK27,"LxE") -> 0 | AS27: =COUNTIF($G27:$AK27,"LA") -> 0 | AT27: =SUM(AP27:AS27) -> 0
A28: Contratado | B28: Becerra, Abigail Ayelen | C28: 40240445 | D28: 11-6545-7404 | E28: AYTE. JS | F28: Italia 339, Barrio Canguro, San Martin | G28: LA | H28: LA | I28: LA | J28: LA | K28: LA | L28: LA | P28: P | R28: P | T28: P | V28: LLT | X28: P | Z28: P | AD28: P | AF28: P | AH28: P | AJ28: P | AN28: =IFS(AO28>3,"NO CORRESPONDE FRANCO",AT28>0,"NO CORRESPONDE FRANCO",AT28=0,"") -> NO CORRESPONDE FRANCO | AO28: =COUNTIF($G28:$AK28,"LLT") -> 1 | AP28: =COUNTIF($G28:$AK28,"LM") -> 0 | AQ28: =COUNTIF($G28:$AK28,"FaC") -> 0 | AR28: =COUNTIF($G28:$AK28,"LxE") -> 0 | AS28: =COUNTIF($G28:$AK28,"LA") -> 6 | AT28: =SUM(AP28:AS28) -> 6
A29: Contratado | B29: Verdura Elias | C29: 46749945 | D29: 11-5326-4477 | E29: SAE | F29: Jose Maria Moreno 3240 Lanus | H29: P | J29: P | L29: CG | P29: P | Q29: P | R29: P | T29: P | V29: P | X29: p | Y29: P | Z29: FA | AD29: LA | AE29: LA | AF29: LA | AG29: LA | AH29: LA | AI29: LA | AJ29: LA | AN29: =IFS(AO29>3,"NO CORRESPONDE FRANCO",AT29>0,"NO CORRESPONDE FRANCO",AT29=0,"") -> NO CORRESPONDE FRANCO | AO29: =COUNTIF($G29:$AK29,"LLT") -> 0 | AP29: =COUNTIF($G29:$AK29,"LM") -> 0 | AQ29: =COUNTIF($G29:$AK29,"FaC") -> 0 | AR29: =COUNTIF($G29:$AK29,"LxE") -> 0 | AS29: =COUNTIF($G29:$AK29,"LA") -> 7 | AT29: =SUM(AP29:AS29) -> 7
A30: Contratado | B30: Rojas Nicole | C30: 42661512 | D30: 11-3508-6789 | E30: HECHOS ESPECÍFICOS | F30: Av. Perito Moreno 1631 N°255 | H30: LLT | J30: LLT | L30: P | P30: P | R30: P | T30: P | V30: FA | X30: P | Z30: LLT | AD30: LTT | AF30: P | AH30: P | AJ30: P | AN30: =IFS(AO30>3,"NO CORRESPONDE FRANCO",AT30>0,"NO CORRESPONDE FRANCO",AT30=0,"") | AO30: =COUNTIF($G30:$AK30,"LLT") -> 2 | AP30: =COUNTIF($G30:$AK30,"LM") -> 0 | AQ30: =COUNTIF($G30:$AK30,"FaC") -> 0 | AR30: =COUNTIF($G30:$AK30,"LxE") -> 0 | AS30: =COUNTIF($G30:$AK30,"LA") -> 0 | AT30: =SUM(AP30:AS30) -> 0
A31: Contratado | B31: Rivera, Daniela Alejandra | C31: 43318554 | D31: 11-7081-6674 | E31: SAE | F31: Brasil 3771 - San Justo | H31: P | J31: P | L31: P | P31: LA | Q31: LA | R31: LA | S31: LA | T31: LA | U31: LA | V31: LA | X31: P | Z31: FA | AD31: P | AF31: P | AH31: P | AJ31: P | AN31: =IFS(AO31>3,"NO CORRESPONDE FRANCO",AT31>0,"NO CORRESPONDE FRANCO",AT31=0,"") -> NO CORRESPONDE FRANCO | AO31: =COUNTIF($G31:$AK31,"LLT") -> 0 | AP31: =COUNTIF($G31:$AK31,"LM") -> 0 | AQ31: =COUNTIF($G31:$AK31,"FaC") -> 0 | AR31: =COUNTIF($G31:$AK31,"LxE") -> 0 | AS31: =COUNTIF($G31:$AK31,"LA") -> 7 | AT31: =SUM(AP31:AS31) -> 7
A32: Contratado | B32: Veltri, Paula Andrea | C32: 31821827 | D32: 11-6153-3734 | E32: SISEP | F32: Neuquen 2035 2E- Flores | H32: P | J32: LLT | L32: P | P32: P | R32: LLT | T32: LLT | V32: LLT | X32: LA | Y32: LA | Z32: LA | AA32: LA | AB32: LA | AC32: LA | AD32: LA | AF32: FA | AH32: FA | AJ32: LLT | AN32: =IFS(AO32>3,"NO CORRESPONDE FRANCO",AT32>0,"NO CORRESPONDE FRANCO",AT32=0,"") -> NO CORRESPONDE FRANCO | AO32: =COUNTIF($G32:$AK32,"LLT") -> 5 | AP32: =COUNTIF($G32:$AK32,"LM") -> 0 | AQ32: =COUNTIF($G32:$AK32,"FaC") -> 0 | AR32: =COUNTIF($G32:$AK32,"LxE") -> 0 | AS32: =COUNTIF($G32:$AK32,"LA") -> 7 | AT32: =SUM(AP32:AS32) -> 7
A33: Contratado | B33: Gomez, Ramiro Jesus | C33: 44544722 | D33: 11-3606-5080 | E33: SAE | F33: CALLE 844 NUMERO 1600 - QUILMES | H33: P | J33: LLT | L33: LLT | P33: LLT | R33: P | T33: FA | V33: LM | W33: LM | X33: P | Z33: P | AD33: LTT | AF33: P | AH33: LM | AI33: LM | AJ33: LM | AN33: =IFS(AO33>3,"NO CORRESPONDE FRANCO",AT33>0,"NO CORRESPONDE FRANCO",AT33=0,"") -> NO CORRESPONDE FRANCO | AO33: =COUNTIF($G33:$AK33,"LLT") -> 3 | AP33: =COUNTIF($G33:$AK33,"LM") -> 5 | AQ33: =COUNTIF($G33:$AK33,"FaC") -> 0 | AR33: =COUNTIF($G33:$AK33,"LxE") -> 0 | AS33: =COUNTIF($G33:$AK33,"LA") -> 0 | AT33: =SUM(AP33:AS33) -> 5
A34: Contratado | B34: Gonzalez, Rocio Macarena | C34: 43319446 | D34: 11-3494-5868 | E34: HECHOS ESPECÍFICOS | F34: Juan B. Justo 3720 - CABA | H34: LLT | J34: P | L34: P | P34: P | R34: P | T34: P | V34: LLT | X34: P | Z34: P | AD34: LM | AF34: P | AH34: P | AJ34: FA | AN34: =IFS(AO34>3,"NO CORRESPONDE FRANCO",AT34>0,"NO CORRESPONDE FRANCO",AT34=0,"") -> NO CORRESPONDE FRANCO | AO34: =COUNTIF($G34:$AK34,"LLT") -> 2 | AP34: =COUNTIF($G34:$AK34,"LM") -> 1 | AQ34: =COUNTIF($G34:$AK34,"FaC") -> 0 | AR34: =COUNTIF($G34:$AK34,"LxE") -> 0 | AS34: =COUNTIF($G34:$AK34,"LA") -> 0 | AT34: =SUM(AP34:AS34) -> 1
A35: Contratado | B35: Gonzalez, Carolina Alejandra | C35: 37214657 | D35: 11-2525-0946 | E35: HECHOS ESPECÍFICOS | F35: Juan B. Justo 3720 - CABA | H35: LLT | J35: P | L35: P | P35: P | R35: P | T35: P | V35: LLT | X35: P | Z35: P | AD35: P | AF35: P | AH35: P | AJ35: LM | AN35: =IFS(AO35>3,"NO CORRESPONDE FRANCO",AT35>0,"NO CORRESPONDE FRANCO",AT35=0,"") -> NO CORRESPONDE FRANCO | AO35: =COUNTIF($G35:$AK35,"LLT") -> 2 | AP35: =COUNTIF($G35:$AK35,"LM") -> 1 | AQ35: =COUNTIF($G35:$AK35,"FaC") -> 0 | AR35: =COUNTIF($G35:$AK35,"LxE") -> 0 | AS35: =COUNTIF($G35:$AK35,"LA") -> 0 | AT35: =SUM(AP35:AS35) -> 1
A36: Contratado | B36: Torres, Paola Herminia | C36: 29157382 | D36: 11-5345-7109 | E36: HECHOS ESPECÍFICOS | F36: Tandil 4380 CASA - Parque Avellaneda | H36: FA | J36: LLT | L36: P | P36: P | R36: P | T36: LLT | V36: FA | X36: P | Z36: P | AD36: P | AF36: P | AH36: P | AJ36: P | AN36: =IFS(AO36>3,"NO CORRESPONDE FRANCO",AT36>0,"NO CORRESPONDE FRANCO",AT36=0,"") | AO36: =COUNTIF($G36:$AK36,"LLT") -> 2 | AP36: =COUNTIF($G36:$AK36,"LM") -> 0 | AQ36: =COUNTIF($G36:$AK36,"FaC") -> 0 | AR36: =COUNTIF($G36:$AK36,"LxE") -> 0 | AS36: =COUNTIF($G36:$AK36,"LA") -> 0 | AT36: =SUM(AP36:AS36) -> 0
A37: Contratado | B37: Uzcategui Floranyely | C37: 96200093 | D37: 11-4400-1306 | E37: SAE | F37: Bartolomé Mitre 3793- Almagro | H37: P | J37: P | L37: P | P37: P | R37: P | T37: P | V37: P | X37: P | Z37: P | AD37: P | AF37: P | AH37: P | AJ37: LM | AN37: =IFS(AO37>3,"NO CORRESPONDE FRANCO",AT37>0,"NO CORRESPONDE FRANCO",AT37=0,"") -> NO CORRESPONDE FRANCO | AO37: =COUNTIF($G37:$AK37,"LLT") -> 0 | AP37: =COUNTIF($G37:$AK37,"LM") -> 1 | AQ37: =COUNTIF($G37:$AK37,"FaC") -> 0 | AR37: =COUNTIF($G37:$AK37,"LxE") -> 0 | AS37: =COUNTIF($G37:$AK37,"LA") -> 0 | AT37: =SUM(AP37:AS37) -> 1
A38: Contratado | B38: Fernández, Ruth | C38: 34514275 | D38: 11 2274-2849 | E38: GRUPO ESPECIFICO DE INTERVENCION RAPIDA | F38: Villegas 353 - El Palomar | R38: P | T38: P | V38: FA | X38: P | Z38: P | AD38: P | AF38: P | AH38: P | AJ38: P | AN38: =IFS(AO38>3,"NO CORRESPONDE FRANCO",AT38>0,"NO CORRESPONDE FRANCO",AT38=0,"")
A39: Contratado | B39: Perez, Agustina | C39: 46936229 | D39: 11-2842-2895 | E39: ADM | F39: Calle 893 entre 801 y 802 N° 1137- Quilmes | AF39: P | AG39: P | AH39: P | AJ39: P | AN39: =IFS(AO39>3,"NO CORRESPONDE FRANCO",AT39>0,"NO CORRESPONDE FRANCO",AT39=0,"")
A40: CMU PUERTO MADERO
...

Sheet TURNO MAÑANA 06 A 14 HS
A2: GRUPO "A" TM - 06 A 14 HS | F2: 1 | G2: 2 | H2: 3 | I2: 4 | J2: 5 | K2: 6 | L2: 7 | M2: 8 | N2: 9 | O2: 10 | P2: 11 | Q2: 12 | R2: 13 | S2: 14 | T2: 15 | U2: 16 | V2: 17 | W2: 18 | X2: 19 | Y2: 20 | Z2: 21 | AA2: 22 | AB2: 23 | AC2: 24 | AD2: 25 | AE2: 26 | AF2: 27 | AG2: 28 | AH2: 29 | AI2: 30 | AJ2: 31 | AK2: 9
A3: JERARQUIA | B3: NOMBRE Y APELLIDO | C3: LP/DNI | D3: DOMICILIO | E3: CELULAR | F3: S | G3: D | H3: L | I3: M | J3: M | K3: J | L3: V | M3: S | N3: D | O3: L | P3: M | Q3: M | R3: J | S3: V | T3: S | U3: D | V3: L | W3: M | X3: M | Y3: J | Z3: V | AA3: S | AB3: D | AC3: L | AD3: M | AE3: M | AF3: J | AG3: V | AH3: S | AI3: D | AJ3: L | AM3: Observaciones | AN3: LLT | AO3: LM | AP3: FAC | AQ3: LXE | AR3: LA
A4: NIVEL J | B4: Aisimburo, Jazmín | C4: 13782 | D4: MAZA 1009 - CABA | E4: 11-5709-7830 | F4: P | H4: P | L4: P | M4: P | N4: P | O4: P | S4: P | U4: PASA A DIVISION ANALISIS DE IMAGENES | AM4: =IFS(AN4>3,"NO CORRESPONDE FRANCO",AS4>0,"NO CORRESPONDE FRANCO",AS4=0,"") | AN4: =COUNTIF($F4:$AJ4,"LLT") -> 0 | AO4: =COUNTIF($F4:$AJ4,"LM") -> 0 | AP4: =COUNTIF($F4:$AJ4,"FaC") -> 0 | AQ4: =COUNTIF($F4:$AJ4,"LxE") -> 0 | AR4: =COUNTIF($F4:$AJ4,"LA") -> 0 | AS4: =SUM(AO4:AR4) -> 0
A5: Contratado | B5: Benditti, Julieta | C5: 38919576 | D5: LARREA 1105- SAN MIGUEL | E5: 11-3251-4862 | F5: P | G5: P | H5: P | L5: P | M5: P | N5: P | O5: LM | R5: P | S5: P | T5: P | X5: FA | Y5: P | Z5: P | AA5: P | AD5: P | AE5: P | AF5: P | AH5: P | AJ5: CG | AM5: =IFS(AN5>3,"NO CORRESPONDE FRANCO",AS5>0,"NO CORRESPONDE FRANCO",AS5=0,"") -> NO CORRESPONDE FRANCO | AN5: =COUNTIF($F5:$AJ5,"LLT") -> 0 | AO5: =COUNTIF($F5:$AJ5,"LM") -> 1 | AP5: =COUNTIF($F5:$AJ5,"FaC") -> 0 | AQ5: =COUNTIF($F5:$AJ5,"LxE") -> 0 | AR5: =COUNTIF($F5:$AJ5,"LA") -> 0 | AS5: =SUM(AO5:AR5) -> 1
A6: Contratado | B6: Diaz, María Belén | C6: 35166947 | D6: Lope de Vega 3469 6b, CABA | E6: 11-6443-4958 | F6: P | G6: CG | H6: P | L6: P | M6: P | N6: LM | O6: P | R6: P | S6: LLT | T6: P | X6: P | Y6: P | Z6: P | AA6: FA | AD6: P | AE6: P | AF6: P | AH6: P | AJ6: P | AM6: =IFS(AN6>3,"NO CORRESPONDE FRANCO",AS6>0,"NO CORRESPONDE FRANCO",AS6=0,"") -> NO CORRESPONDE FRANCO | AN6: =COUNTIF($F6:$AJ6,"LLT") -> 1 | AO6: =COUNTIF($F6:$AJ6,"LM") -> 1 | AP6: =COUNTIF($F6:$AJ6,"FaC") -> 0 | AQ6: =COUNTIF($F6:$AJ6,"LxE") -> 0 | AR6: =COUNTIF($F6:$AJ6,"LA") -> 0 | AS6: =SUM(AO6:AR6) -> 1
A7: Contratado | B7: Bergara, Andrea Carolina | C7: 92902672 | D7: Pola 1599 - CABA | E7: 11-5416-3984 | F7: LLT | G7: P | H7: P | L7: P | M7: P | N7: P | O7: P | R7: P | S7: P | T7: LLT | U7: P | X7: P | Y7: P | Z7: P | AA7: P | AD7: P | AE7: P | AF7: P | AJ7: CG | AM7: =IFS(AN7>3,"NO CORRESPONDE FRANCO",AS7>0,"NO CORRESPONDE FRANCO",AS7=0,"") | AN7: =COUNTIF($F7:$AJ7,"LLT") -> 2 | AO7: =COUNTIF($F7:$AJ7,"LM") -> 0 | AP7: =COUNTIF($F7:$AJ7,"FaC") -> 0 | AQ7: =COUNTIF($F7:$AJ7,"LxE") -> 0 | AR7: =COUNTIF($F7:$AJ7,"LA") -> 0 | AS7: =SUM(AO7:AR7) -> 0
A8: Contratado | B8: Telvini, Tiago | C8: 45286302 | D8: Ocampo 2280- Hurlingham | E8: 11-5981-7211 | F8: P | G8: P | H8: LLT | L8: P | M8: P | N8: P | O8: LLT | R8: LLT | S8: P | T8: LLT | X8: P | Y8: P | Z8: P | AA8: LM | AD8: P | AE8: LTT | AF8: LLT | AJ8: P | AM8: =IFS(AN8>3,"NO CORRESPONDE FRANCO",AS8>0,"NO CORRESPONDE FRANCO",AS8=0,"") -> NO CORRESPONDE FRANCO | AN8: =COUNTIF($F8:$AJ8,"LLT") -> 5 | AO8: =COUNTIF($F8:$AJ8,"LM") -> 1 | AP8: =COUNTIF($F8:$AJ8,"FaC") -> 0 | AQ8: =COUNTIF($F8:$AJ8,"LxE") -> 0 | AR8: =COUNTIF($F8:$AJ8,"LA") -> 0 | AS8: =SUM(AO8:AR8) -> 1
A9: Contratado | B9: Torrez Hurtado, Nayra | C9: 46438246 | D9: Av. La Plata 1781 - CABA | E9: 11-5703-5949 | L9: P | M9: P | N9: LLT | O9: LLT | R9: P | S9: LLT | T9: LLT | X9: P | Y9: P | Z9: LLT | AD9: P | AE9: LLT | AF9: LLT | AJ9: LLT | AM9: =IFS(AN9>3,"NO CORRESPONDE FRANCO",AS9>0,"NO CORRESPONDE FRANCO",AS9=0,"")
A10: Contratado | B10: Sanabria Melina | C10: 36483668 | D10: Santa Fe N°164 - GUERNICA | E10: 11-3236-4349 | F10: LLT | G10: P | H10: P | L10: LLT | M10: LM | N10: LM | O10: LM | R10: FAC | S10: FAC | T10: FAC | X10: LLT | Y10: LM | Z10: LLT | AA10: LLT | AD10: P | AE10: LLT | AF10: LM | AJ10: LM | AK10: HORARIO REDUCIDO POR LACTANCIA HASTA 21/10/2026 de 10 a 16HS | AM10: =IFS(AN10>3,"NO CORRESPONDE FRANCO",AS10>0,"NO CORRESPONDE FRANCO",AS10=0,"") -> NO CORRESPONDE FRANCO | AN10: =COUNTIF($F10:$AJ10,"LLT") -> 6 | AO10: =COUNTIF($F10:$AJ10,"LM") -> 6 | AP10: =COUNTIF($F10:$AJ10,"FaC") -> 3 | AQ10: =COUNTIF($F10:$AJ10,"LxE") -> 0 | AR10: =COUNTIF($F10:$AJ10,"LA") -> 0 | AS10: =SUM(AO10:AR10) -> 9
A11: Contratado | B11: Revainera Florencia | C11: 34566476 | D11: Calle 158 y 18, Monoblock 14 S/N-Berazategui | E11: 11-57443390 | F11: CG | G11: P | H11: P | J11: P | K11: P | L11: P | M11: P | N11: FA | O11: LA | P11: LA | Q11: LA | R11: LA | S11: LA | T11: LA | U11: LA | X11: P | Y11: P | Z11: P | AA11: LLT | AD11: P | AE11: CG | AF11: P | AG11: LLT | AH11: P | AJ11: CG | AM11: =IFS(AN11>3,"NO CORRESPONDE FRANCO",AS11>0,"NO CORRESPONDE FRANCO",AS11=0,"") -> NO CORRESPONDE FRANCO | AN11: =COUNTIF($F11:$AJ11,"LLT") -> 2 | AO11: =COUNTIF($F11:$AJ11,"LM") -> 0 | AP11: =COUNTIF($F11:$AJ11,"FaC") -> 0 | AQ11: =COUNTIF($F11:$AJ11,"LxE") -> 0 | AR11: =COUNTIF($F11:$AJ11,"LA") -> 7 | AS11: =SUM(AO11:AR11) -> 7
A12: Contratado | B12: Goncalves Ferreira Valentino | C12: 46293557 | D12: Rio Negro 740- El Palomar | E12: 11-36509379 | F12: P | G12: P | H12: P | L12: P | M12: FA | N12: P | O12: P | R12: P | S12: P | T12: P | X12: P | Y12: P | Z12: P | AA12: P | AD12: P | AE12: P | AF12: P | AJ12: P | AM12: =IFS(AN12>3,"NO CORRESPONDE FRANCO",AS12>0,"NO CORRESPONDE FRANCO",AS12=0,"") | AN12: =COUNTIF($F12:$AJ12,"LLT") -> 0 | AO12: =COUNTIF($F12:$AJ12,"LM") -> 0 | AP12: =COUNTIF($F12:$AJ12,"FaC") -> 0 | AQ12: =COUNTIF($F12:$AJ12,"LxE") -> 0 | AR12: =COUNTIF($F12:$AJ12,"LA") -> 0 | AS12: =SUM(AO12:AR12) -> 0
A13: Contratado | B13: Espinola Carolina | C13: 44260361 | D13: Benito Alvarez 541 La Matanza | E13: 11-67453824 | F13: LLT | G13: LLT | H13: LLT | L13: LA | M13: LA | N13: LA | O13: LA | P13: LA | Q13: LA | R13: LA | S13: P | T13: FA | X13: P | Y13: P | Z13: LLT | AA13: LLT | AD13: LLT | AE13: P | AJ13: P | AK13: DIAS DE SEMANA SE RETIRA 13:40HS | AM13: =IFS(AN13>3,"NO CORRESPONDE FRANCO",AS13>0,"NO CORRESPONDE FRANCO",AS13=0,"") -> NO CORRESPONDE FRANCO | AN13: =COUNTIF($F13:$AJ13,"LLT") -> 6 | AO13: =COUNTIF($F13:$AJ13,"LM") -> 0 | AP13: =COUNTIF($F13:$AJ13,"FaC") -> 0 | AQ13: =COUNTIF($F13:$AJ13,"LxE") -> 0 | AR13: =COUNTIF($F13:$AJ13,"LA") -> 7 | AS13: =SUM(AO13:AR13) -> 7
A14: Contratado | B14: Santellan, Jonathan Sebastian | C14: 27928430 | D14: Yerbal 6142 - CABA | E14: 11-5047-1579 | F14: P | G14: P | H14: P | L14: LA | M14: LA | N14: LA | O14: LA | P14: LA | Q14: LA | R14: LA | S14: FA | T14: LLT | X14: P | Y14: P | Z14: P | AA14: P | AD14: P | AE14: P | AF14: P | AJ14: P | AM14: =IFS(AN14>3,"NO CORRESPONDE FRANCO",AS14>0,"NO CORRESPONDE FRANCO",AS14=0,"") -> NO CORRESPONDE FRANCO | AN14: =COUNTIF($F14:$AJ14,"LLT") -> 1 | AO14: =COUNTIF($F14:$AJ14,"LM") -> 0 | AP14: =COUNTIF($F14:$AJ14,"FaC") -> 0 | AQ14: =COUNTIF($F14:$AJ14,"LxE") -> 0 | AR14: =COUNTIF($F14:$AJ14,"LA") -> 7 | AS14: =SUM(AO14:AR14) -> 7
AK15: DA | AM15: =IFS(AN15>3,"NO CORRESPONDE FRANCO",AS15>0,"NO CORRESPONDE FRANCO",AS15=0,"")
A16: GRUPO "B" TM - 06 A 14 HS | F16: 1 | G16: 2 | H16: 3 | I16: 4 | J16: 5 | K16: 6 | L16: 7 | M16: 8 | N16: 9 | O16: 10 | P16: 11 | Q16: 12 | R16: 13 | S16: 14 | T16: 15 | U16: 16 | V16: 17 | W16: 18 | X16: 19 | Y16: 20 | Z16: 21 | AA16: 22 | AB16: 23 | AC16: 24 | AD16: 25 | AE16: 26 | AF16: 27 | AG16: 28 | AH16: 29 | AI16: 30 | AJ16: 31 | AM16: =IFS(AN16>3,"NO CORRESPONDE FRANCO",AS16>0,"NO CORRESPONDE FRANCO",AS16=0,"")
A17: JERARQUIA | B17: NOMBRE Y APELLIDO | C17: LP/DNI | D17: DOMICILIO | E17: CELULAR | F17: S | G17: D | H17: L | I17: M | J17: M | K17: J | L17: V | M17: S | N17: D | O17: L | P17: M | Q17: M | R17: J | S17: V | T17: S | U17: D | V17: L | W17: M | X17: M | Y17: J | Z17: V | AA17: S | AB17: D | AC17: L | AD17: M | AE17: M | AF17: J | AG17: V | AH17: S | AI17: D | AJ17: L | AM17: =IFS(AN17>3,"NO CORRESPONDE FRANCO",AS17>0,"NO CORRESPONDE FRANCO",AS17=0,"")
A18: Nivel J | B18: Penovi, Lucas | C18: 12141 | D18: Mendoza 224 2 C - Moron | E18: 11-3005-8475 | F18: LLT | G18: LLT | H18: LLT | I18: LLT | M18: P | N18: P | O18: P | R18: P | S18: LLT | T18: LLT | U18: LLT | Y18: P | Z18: P | AA18: LLT | AD18: P | AE18: P | AF18: LLT | AG18: LLT | AK18: Cumple servicio de 07 a 15Hs | AM18: =IFS(AN18>3,"NO CORRESPONDE FRANCO",AS18>0,"NO CORRESPONDE FRANCO",AS18=0,"") -> NO CORRESPONDE FRANCO | AN18: =COUNTIF($F18:$AJ18,"LLT") -> 9 | AO18: =COUNTIF($F18:$AJ18,"LM") -> 0 | AP18: =COUNTIF($F18:$AJ18,"FaC") -> 0 | AQ18: =COUNTIF($F18:$AJ18,"LxE") -> 0 | AR18: =COUNTIF($F18:$AJ18,"LA") -> 0 | AS18: =SUM(AO18:AR18) -> 0
A19: Nivel J | B19: Ibarra Veronica | C19: 13872 | D19: BLAS PARERA 871-LIBERTAD BS AS | E19: 11-3360-7862 | F19: LM | G19: LM | H19: LM | I19: LM | J19: LM | K19: LM | L19: LM | M19: LM | N19: LM | O19: LM | P19: LM | Q19: LM | R19: LM | S19: LM | T19: LM | U19: LM | V19: LM | W19: LM | X19: LM | Y19: LM | Z19: LM | AA19: LM | AB19: LM | AC19: LM | AD19: LM | AE19: LM | AF19: LM | AG19: LM | AH19: LM | AI19: LM | AJ19: LM | AK19: LM jasta 12/09 | AM19: =IFS(AN19>3,"NO CORRESPONDE FRANCO",AS19>0,"NO CORRESPONDE FRANCO",AS19=0,"") -> NO CORRESPONDE FRANCO | AN19: =COUNTIF($F19:$AJ19,"LLT") -> 0 | AO19: =COUNTIF($F19:$AJ19,"LM") -> 31 | AP19: =COUNTIF($F19:$AJ19,"FaC") -> 0 | AQ19: =COUNTIF($F19:$AJ19,"LxE") -> 0 | AR19: =COUNTIF($F19:$AJ19,"LA") -> 0 | AS19: =SUM(AO19:AR19) -> 31
A20: Contratado | B20: Koselstein, Silvina | C20: 24293262 | D20: CAAGUAZU 6911 DTO2 – CABA | E20: 11-2465-0440 | F20: LM | G20: LM | H20: LM | I20: LM | J20: LM | K20: LM | L20: LM | M20: LM | N20: LM | O20: LM | P20: LM | Q20: LM | R20: LM | S20: LM | T20: LM | U20: LM | V20: LM | W20: LM | X20: LM | Y20: LM | Z20: LM | AA20: LM | AB20: LM | AC20: LM | AD20: LM | AE20: LM | AF20: LM | AG20: LM | AH20: LM | AI20: LM | AJ20: LM | AK20: LM hasta 04/09 | AM20: =IFS(AN20>3,"NO CORRESPONDE FRANCO",AS20>0,"NO CORRESPONDE FRANCO",AS20=0,"") -> NO CORRESPONDE FRANCO | AN20: =COUNTIF($F20:$AJ20,"LLT") -> 0 | AO20: =COUNTIF($F20:$AJ20,"LM") -> 31 | AP20: =COUNTIF($F20:$AJ20,"FaC") -> 0 | AQ20: =COUNTIF($F20:$AJ20,"LxE") -> 0 | AR20: =COUNTIF($F20:$AJ20,"LA") -> 0 | AS20: =SUM(AO20:AR20) -> 31
A21: Contratado | B21: Romero, Graciela | C21: 30353085 | D21: MARTIN GARCIA MEROU 4738- LAFERRERE | E21: 11-3935-1209 | F21: LLT | G21: P | H21: P | I21: P | M21: LA | N21: LA | O21: LA | P21: LA | Q21: LA | R21: LA | S21: LA | T21: CG | U21: FA | Y21: FA | Z21: P | AA21: P | AB21: P | AD21: LM | AE21: LM | AF21: P | AG21: P | AM21: =IFS(AN21>3,"NO CORRESPONDE FRANCO",AS21>0,"NO CORRESPONDE FRANCO",AS21=0,"") -> NO CORRESPONDE FRANCO | AN21: =COUNTIF($F21:$AJ21,"LLT") -> 1 | AO21: =COUNTIF($F21:$AJ21,"LM") -> 2 | AP21: =COUNTIF($F21:$AJ21,"FaC") -> 0 | AQ21: =COUNTIF($F21:$AJ21,"LxE") -> 0 | AR21: =COUNTIF($F21:$AJ21,"LA") -> 7 | AS21: =SUM(AO21:AR21) -> 9
A22: Contratado | B22: Camaño, Nahuel Elias | C22: 44006317 | D22: PAEZ 927-RAMOS MEJIA | E22: 11-2238-1543 | F22: P | G22: P | H22: P | I22: P | M22: P | N22: P | O22: P | P22: LLT | R22: CG | S22: LLT | T22: LLT | U22: P | W22: F | Y22: LLT | Z22: P | AA22: P | AD22: P | AE22: P | AF22: LLT | AG22: P | AM22: =IFS(AN22>3,"NO CORRESPONDE FRANCO",AS22>0,"NO CORRESPONDE FRANCO",AS22=0,"") -> NO CORRESPONDE FRANCO | AN22: =COUNTIF($F22:$AJ22,"LLT") -> 5 | AO22: =COUNTIF($F22:$AJ22,"LM") -> 0 | AP22: =COUNTIF($F22:$AJ22,"FaC") -> 0 | AQ22: =COUNTIF($F22:$AJ22,"LxE") -> 0 | AR22: =COUNTIF($F22:$AJ22,"LA") -> 0 | AS22: =SUM(AO22:AR22) -> 0
A23: Contratado | B23: Galeano, Belen Noemí | C23: 45227870 | D23: CALLE 32 ENTRE 20 Y 21- GUERNICA | E23: 11-6746-7004 | F23: LLT | G23: LM | H23: LM | I23: P | M23: P | N23: LLT | O23: P | R23: P | S23: LM | T23: LLT | U23: LM | Y23: P | Z23: LM | AA23: LM | AD23: P | AE23: LM | AF23: LLT | AG23: P | AK23: Horario de lactancia de 06 a 12hs hasta 29/03/2027 | AM23: =IFS(AN23>3,"NO CORRESPONDE FRANCO",AS23>0,"NO CORRESPONDE FRANCO",AS23=0,"") -> NO CORRESPONDE FRANCO | AN23: =COUNTIF($F23:$AJ23,"LLT") -> 4 | AO23: =COUNTIF($F23:$AJ23,"LM") -> 7 | AP23: =COUNTIF($F23:$AJ23,"FaC") -> 0 | AQ23: =COUNTIF($F23:$AJ23,"LxE") -> 0 | AR23: =COUNTIF($F23:$AJ23,"LA") -> 0 | AS23: =SUM(AO23:AR23) -> 7
A24: Contratado | B24: Vorpagel, Sabrina | C24: 40835168 | D24: Rio diamante 1442 - Bella Vista | E24: 11-3442-8559 | F24: P | G24: P | H24: P | I24: P | M24: P | N24: P | O24: P | R24: P | S24: P | T24: P | U24: LLT | Y24: P | Z24: P | AA24: P | AD24: P | AE24: P | AF24: P | AG24: P | AM24: =IFS(AN24>3,"NO CORRESPONDE FRANCO",AS24>0,"NO CORRESPONDE FRANCO",AS24=0,"") | AN24: =COUNTIF($F24:$AJ24,"LLT") -> 1 | AO24: =COUNTIF($F24:$AJ24,"LM") -> 0 | AP24: =COUNTIF($F24:$AJ24,"FaC") -> 0 | AQ24: =COUNTIF($F24:$AJ24,"LxE") -> 0 | AR24: =COUNTIF($F24:$AJ24,"LA") -> 0 | AS24: =SUM(AO24:AR24) -> 0
A25: Contratado | B25: Vorpagel, Agustina | C25: 46089146 | D25: PASCUALA ACUETO- 1300- SAN MIGUEL | E25: 11-2797-4970 | F25: LM | G25: LM | H25: LM | I25: P | M25: P | N25: LLT | O25: P | R25: P | S25: P | T25: P | U25: LLT | Y25: P | Z25: P | AA25: P | AD25: FA | AE25: P | AF25: P | AG25: P | AM25: =IFS(AN25>3,"NO CORRESPONDE FRANCO",AS25>0,"NO CORRESPONDE FRANCO",AS25=0,"") -> NO CORRESPONDE FRANCO | AN25: =COUNTIF($F25:$AJ25,"LLT") -> 2 | AO25: =COUNTIF($F25:$AJ25,"LM") -> 3 | AP25: =COUNTIF($F25:$AJ25,"FaC") -> 0 | AQ25: =COUNTIF($F25:$AJ25,"LxE") -> 0 | AR25: =COUNTIF($F25:$AJ25,"LA") -> 0 | AS25: =SUM(AO25:AR25) -> 3
A26: Contratado | B26: Vesga Ivana | C26: 35761085 | D26: Nuñez de Arce 197 Banfield | E26: 11-60168265 | F26: LLT | G26: LLT | H26: LLT | I26: LLT | M26: P | N26: P | O26: P | R26: P | S26: P | T26: P | U26: P | Y26: P | Z26: P | AA26: P | AD26: P | AE26: P | AF26: P | AG26: P | AM26: =IFS(AN26>3,"NO CORRESPONDE FRANCO",AS26>0,"NO CORRESPONDE FRANCO",AS26=0,"") -> NO CORRESPONDE FRANCO | AN26: =COUNTIF($F26:$AJ26,"LLT") -> 4 | AO26: =COUNTIF($F26:$AJ26,"LM") -> 0 | AP26: =COUNTIF($F26:$AJ26,"FaC") -> 0 | AQ26: =COUNTIF($F26:$AJ26,"LxE") -> 0 | AR26: =COUNTIF($F26:$AJ26,"LA") -> 0 | AS26: =SUM(AO26:AR26) -> 0
A27: Contratado | B27: Arrigoni Ailin Lucila | C27: 39654955 | D27: Timoteo Gordillo 2674-Mataderos | E27: 1540317250 | F27: LM | G27: LM | H27: P | I27: P | K27: LM | L27: LM | M27: LM | N27: FA | O27: LM | R27: P | S27: P | T27: P | U27: FA | Y27: P | Z27: P | AA27: LM | AD27: P | AE27: P | AF27: P | AG27: CG | AJ27: P | AM27: =IFS(AN27>3,"NO CORRESPONDE FRANCO",AS27>0,"NO CORRESPONDE FRANCO",AS27=0,"") -> NO CORRESPONDE FRANCO | AN27: =COUNTIF($F27:$AJ27,"LLT") -> 0 | AO27: =COUNTIF($F27:$AJ27,"LM") -> 7 | AP27: =COUNTIF($F27:$AJ27,"FaC") -> 0 | AQ27: =COUNTIF($F27:$AJ27,"LxE") -> 0 | AR27: =COUNTIF($F27:$AJ27,"LA") -> 0 | AS27: =SUM(AO27:AR27) -> 7
A28: Contratado | B28: Cipriano, Facundo Nicolas | C28: 41917769 | D28: Paunero 1582 - La matanza | E28: 11-3485-8925 | F28: P | G28: P | H28: P | I28: P | M28: P | N28: P | O28: P | R28: P | S28: P | T28: P | U28: P | Y28: P | Z28: P | AA28: P | AC28: P | AD28: CG | AE28: P | AF28: P | AG28: FA | AM28: =IFS(AN28>3,"NO CORRESPONDE FRANCO",AS28>0,"NO CORRESPONDE FRANCO",AS28=0,"") | AN28: =COUNTIF($F28:$AJ28,"LLT") -> 0 | AO28: =COUNTIF($F28:$AJ28,"LM") -> 0 | AP28: =COUNTIF($F28:$AJ28,"FaC") -> 0 | AQ28: =COUNTIF($F28:$AJ28,"LxE") -> 0 | AR28: =COUNTIF($F28:$AJ28,"LA") -> 0 | AS28: =SUM(AO28:AR28) -> 0
A29: Contratado | B29: Romanos Brian Nicolas Erik | C29: 43106633 | D29: SANTA MARÍA 3354 SAN MIGUEL | E29: 11-2642-0423 | F29: P | G29: LLT | H29: P | I29: LLT | M29: P | N29: LA | O29: LA | P29: LA | Q29: LA | R29: LA | S29: LA | T29: LA | U29: LA | Y29: P | Z29: P | AA29: P | AD29: LM | AE29: LM | AF29: LLT | AG29: P | AM29: =IFS(AN29>3,"NO CORRESPONDE FRANCO",AS29>0,"NO CORRESPONDE FRANCO",AS29=0,"") -> NO CORRESPONDE FRANCO | AN29: =COUNTIF($F29:$AJ29,"LLT") -> 3 | AO29: =COUNTIF($F29:$AJ29,"LM") -> 2 | AP29: =COUNTIF($F29:$AJ29,"FaC") -> 0 | AQ29: =COUNTIF($F29:$AJ29,"LxE") -> 0 | AR29: =COUNTIF($F29:$AJ29,"LA") -> 8 | AS29: =SUM(AO29:AR29) -> 10
A30: Contratado | B30: Garnica Candela Parvis | C30: 47343587 | D30: Av Derqui 4009 CABA | E30: 11-3859-7268 | W30: P | Z30: P | AD30: P | AK30: 10 A 18HS. | AM30: =IFS(AN30>3,"NO CORRESPONDE FRANCO",AS30>0,"NO CORRESPONDE FRANCO",AS30=0,"")
AM31: =IFS(AN31>3,"NO CORRESPONDE FRANCO",AS31>0,"NO CORRESPONDE FRANCO",AS31=0,"")
AM32: =IFS(AN32>3,"NO CORRESPONDE FRANCO",AS32>0,"NO CORRESPONDE FRANCO",AS32=0,"")
A33: GRUPO "C" TM - 06 A 14 HS | F33: 1 | G33: 2 | H33: 3 | I33: 4 | J33: 5 | K33: 6 | L33: 7 | M33: 8 | N33: 9 | O33: 10 | P33: 11 | Q33: 12 | R33: 13 | S33: 14 | T33: 15 | U33: 16 | V33: 17 | W33: 18 | X33: 19 | Y33: 20 | Z33: 21 | AA33: 22 | AB33: 23 | AC33: 24 | AD33: 25 | AE33: 26 | AF33: 27 | AG33: 28 | AH33: 29 | AI33: 30 | AJ33: 31 | AM33: =IFS(AN33>3,"NO CORRESPONDE FRANCO",AS33>0,"NO CORRESPONDE FRANCO",AS33=0,"")
A34: JERARQUIA | B34: NOMBRE Y APELLIDO | C34: LP/DNI | D34: DOMICILIO | E34: CELULAR | F34: S | G34: D | H34: L | I34: M | J34: M | K34: J | L34: V | M34: S | N34: D | O34: L | P34: M | Q34: M | R34: J | S34: V | T34: S | U34: D | V34: L | W34: M | X34: M | Y34: J | Z34: V | AA34: S | AB34: D | AC34: L | AD34: M | AE34: M | AF34: J | AG34: V | AH34: S | AI34: D | AJ34: L | AM34: =IFS(AN34>3,"NO CORRESPONDE FRANCO",AS34>0,"NO CORRESPONDE FRANCO",AS34=0,"")
A35: Nivel I | B35: Fidel Graciano, Federico | C35: 12434 | D35: LOS ANDES 2174 - FLORENCIO VARELA | E35: 11-6188-0608 / 11-2261-5080 (POC) | F35: LA | G35: LA | H35: LA | I35: LA | J35: LA | K35: P | N35: P | O35: LLT | P35: LLT | Q35: LLT | U35: P | V35: P | W35: LLT | Z35: LLT | AA35: P | AB35: P | AC35: LLT | AG35: LLT | AH35: P | AI35: P | AM35: =IFS(AN35>3,"NO CORRESPONDE FRANCO",AS35>0,"NO CORRESPONDE FRANCO",AS35=0,"") -> NO CORRESPONDE FRANCO | AN35: =COUNTIF($F35:$AJ35,"LLT") -> 7 | AO35: =COUNTIF($F35:$AJ35,"LM") -> 0 | AP35: =COUNTIF($F35:$AJ35,"FaC") -> 0 | AQ35: =COUNTIF($F35:$AJ35,"LxE") -> 0 | AR35: =COUNTIF($F35:$AJ35,"LA") -> 5 | AS35: =SUM(AO35:AR35) -> 5
A36: Nivel I | B36: Olivares, Sabrina | C36: 12899 | D36: Av. Directorio 963 2°B - Caballito - CABA | E36: 11-3594-6013 | I36: LLT | J36: LLT | K36: LLT | N36: LLT | O36: LLT | P36: LLT | Q36: LLT | U36: LLT | V36: LLT | W36: LLT | Z36: P | AA36: P | AB36: LLT | AC36: LLT | AG36: LLT | AH36: LLT | AI36: LLT | AK36: Cumple servicio de 07 a 15Hs | AM36: =IFS(AN36>3,"NO CORRESPONDE FRANCO",AS36>0,"NO CORRESPONDE FRANCO",AS36=0,"") -> NO CORRESPONDE FRANCO | AN36: =COUNTIF($F36:$AJ36,"LLT") -> 15 | AO36: =COUNTIF($F36:$AJ36,"LM") -> 0 | AP36: =COUNTIF($F36:$AJ36,"FaC") -> 0 | AQ36: =COUNTIF($F36:$AJ36,"LxE") -> 0 | AR36: =COUNTIF($F36:$AJ36,"LA") -> 0 | AS36: =SUM(AO36:AR36) -> 0
A37: Contratado | B37: Cardozo, Romina | C37: 32445282 | D37: Azcuenaga 355- San Miguel | E37: 342 5381452 | I37: P | J37: P | K37: P | N37: FA | O37: P | P37: P | Q37: P | U37: CG | V37: P | W37: P | X37: P | Z37: LA | AA37: LA | AB37: LA | AC37: LA | AD37: LA | AG37: CG | AH37: P | AI37: FA | AK37: 1/9 CG LA CUBRE CABRERA | AM37: =IFS(AN37>3,"NO CORRESPONDE FRANCO",AS37>0,"NO CORRESPONDE FRANCO",AS37=0,"") -> NO CORRESPONDE FRANCO | AN37: =COUNTIF($F37:$AJ37,"LLT") -> 0 | AO37: =COUNTIF($F37:$AJ37,"LM") -> 0 | AP37: =COUNTIF($F37:$AJ37,"FaC") -> 0 | AQ37: =COUNTIF($F37:$AJ37,"LxE") -> 0 | AR37: =COUNTIF($F37:$AJ37,"LA") -> 5 | AS37: =SUM(AO37:AR37) -> 5
A38: Contratado | B38: Castaño, Natalia Soledad | C38: 32003476 | D38: Quintana 4856 - San Fernando | E38: 11-5465-1642 | I38: P | J38: P | K38: P | L38: P | N38: FA | O38: P | P38: P | Q38: P | U38: LLT | V38: CG | W38: P | Y38: P | Z38: P | AA38: P | AB38: P | AC38: P | AG38: P | AH38: P | AI38: LLT | AM38: =IFS(AN38>3,"NO CORRESPONDE FRANCO",AS38>0,"NO CORRESPONDE FRANCO",AS38=0,"") | AN38: =COUNTIF($F38:$AJ38,"LLT") -> 2 | AO38: =COUNTIF($F38:$AJ38,"LM") -> 0 | AP38: =COUNTIF($F38:$AJ38,"FaC") -> 0 | AQ38: =COUNTIF($F38:$AJ38,"LxE") -> 0 | AR38: =COUNTIF($F38:$AJ38,"LA") -> 0 | AS38: =SUM(AO38:AR38) -> 0
A39: Contratado | B39: Roa, Abril | C39: 41706256 | D39: Bulnes 1584 CABA | E39: 11-26950112 | F39: LxM | G39: LxM | H39: LxM | I39: LxM | J39: LxM | K39: LxM | L39: LxM | M39: LxM | N39: LxM | O39: LxM | P39: LxM | Q39: LxM | R39: LxM | S39: LxM | T39: LxM | U39: LxM | V39: LxM | W39: LxM | X39: LxM | Y39: LxM | Z39: LxM | AA39: LxM | AB39: LxM | AC39: LxM | AD39: LxM | AE39: LxM | AF39: LxM | AG39: LxM | AH39: LxM | AI39: LxM | AJ39: LxM | AK39: HASTA 13/09 | AM39: =IFS(AN39>3,"NO CORRESPONDE FRANCO",AS39>0,"NO CORRESPONDE FRANCO",AS39=0,"") | AN39: =COUNTIF($F39:$AJ39,"LLT") -> 0 | AO39: =COUNTIF($F39:$AJ39,"LM") -> 0 | AP39: =COUNTIF($F39:$AJ39,"FaC") -> 0 | AQ39: =COUNTIF($F39:$AJ39,"LxE") -> 0 | AR39: =COUNTIF($F39:$AJ39,"LA") -> 0 | AS39: =SUM(AO39:AR39) -> 0
A40: Contratado | B40: Luraschi, Ignacio | C40: 43988966 | D40: Lascano 3818 - Torre A2 Piso 3 - Depto 4 - CABA | E40: 11-3570-5020 | I40: LM | J40: LM | K40: LM | L40: LM | N40: LM | O40: LLT | P40: CG | Q40: P | R40: P | U40: FA | V40: LLT | W40: LLT | Z40: P | AA40: P | AB40: LM | AC40: CG | AD40: P | AG40: P | AH40: P | AI40: P | AM40: =IFS(AN40>3,"NO CORRESPONDE FRANCO",AS40>0,"NO CORRESPONDE FRANCO",AS40=0,"") -> NO CORRESPONDE FRANCO | AN40: =COUNTIF($F40:$AJ40,"LLT") -> 3 | AO40: =COUNTIF($F40:$AJ40,"LM") -> 6 | AP40: =COUNTIF($F40:$AJ40,"FaC") -> 0 | AQ40: =COUNTIF($F40:$AJ40,"LxE") -> 0 | AR40: =COUNTIF($F40:$AJ40,"LA") -> 0 | AS40: =SUM(AO40:AR40) -> 6
A41: Contratado | B41: Suarez Marcos Nahuel | C41: 37341342 | D41: Casa Cuberta Bicentenario - Avellaneda | E41: 15 3275 7717 | H41: LA | I41: LA | J41: LA | K41: LA | L41: LA | M41: LA | N41: LA | O41: LA | P41: LA | Q41: LA | R41: LA | S41: LA | T41: LA | U41: LA | V41: P | W41: P | Z41: P | AA41: P | AB41: P | AC41: P | AG41: P | AH41: P | AI41: P | AM41: =IFS(AN41>3,"NO CORRESPONDE FRANCO",AS41>0,"NO CORRESPONDE FRANCO",AS41=0,"") -> NO CORRESPONDE FRANCO | AN41: =COUNTIF($F41:$AJ41,"LLT") -> 0 | AO41: =COUNTIF($F41:$AJ41,"LM") -> 0 | AP41: =COUNTIF($F41:$AJ41,"FaC") -> 0 | AQ41: =COUNTIF($F41:$AJ41,"LxE") -> 0 | AR41: =COUNTIF($F41:$AJ41,"LA") -> 14 | AS41: =SUM(AO41:AR41) -> 14
...

Sheet TURNO TARDE DE 14 A 22 HS
F1: 1 | G1: 2 | H1: 3 | I1: 4 | J1: 5 | K1: 6 | L1: 7 | M1: 8 | N1: 9 | O1: 10 | P1: 11 | Q1: 12 | R1: 13 | S1: 14 | T1: 15 | U1: 16 | V1: 17 | W1: 18 | X1: 19 | Y1: 20 | Z1: 21 | AA1: 22 | AB1: 23 | AC1: 24 | AD1: 25 | AE1: 26 | AF1: 27 | AG1: 28 | AH1: 29 | AI1: 30 | AJ1: 31
A2: JERARQUIA | B2: NOMBRE Y APELLIDO | C2: LP/DNI | D2: DOMICILIO | E2: CELULAR | F2: S | G2: D | H2: L | I2: M | J2: M | K2: J | L2: V | M2: S | N2: D | O2: L | P2: M | Q2: M | R2: J | S2: V | T2: S | U2: D | V2: L | W2: M | X2: M | Y2: J | Z2: V | AA2: S | AB2: D | AC2: L | AD2: M | AE2: M | AF2: J | AG2: V | AH2: S | AI2: D | AJ2: L | AM2: Observaciones | AN2: LLT | AO2: LM | AP2: FAC | AQ2: LXE | AR2: LA
A3: Nivel J | B3: Isleño, Lucas | C3: 11675 | D3: NOGOYA 3257 – CABA | E3: 11-3481-4983 | G3: P | H3: P | L3: P | N3: P | O3: P | R3: P | S3: P | Y3: P | Z3: P | AD3: P | AJ3: P | AK3: No presta servicio los dias Miercoles y sabados | AM3: =IFS(AN3>3,"NO CORRESPONDE FRANCO",AS3>0,"NO CORRESPONDE FRANCO",AS3=0,"") | AN3: =COUNTIF($F3:$AJ3,"LLT") -> 0 | AO3: =COUNTIF($F3:$AJ3,"LM") -> 0 | AP3: =COUNTIF($F3:$AJ3,"FaC") -> 0 | AQ3: =COUNTIF($F3:$AJ3,"LxE") -> 0 | AR3: =COUNTIF($F3:$AJ3,"LA") -> 0 | AS3: =SUM(AO3:AR3) -> 0
A4: Contratado | B4: Pérez, Matías Fabián | C4: 44868083 | D4: MAGALLANES 817, REMEDIOS DE ESCALADA | E4: 11-4492-7278 | F4: P | G4: P | H4: P | L4: P | M4: LLT | N4: P | O4: FA | R4: P | S4: LLT | T4: P | X4: P | Y4: LLT | Z4: LLT | AA4: P | AD4: P | AE4: P | AF4: P | AJ4: P | AM4: =IFS(AN4>3,"NO CORRESPONDE FRANCO",AS4>0,"NO CORRESPONDE FRANCO",AS4=0,"") -> NO CORRESPONDE FRANCO | AN4: =COUNTIF($F4:$AJ4,"LLT") -> 4 | AO4: =COUNTIF($F4:$AJ4,"LM") -> 0 | AP4: =COUNTIF($F4:$AJ4,"FaC") -> 0 | AQ4: =COUNTIF($F4:$AJ4,"LxE") -> 0 | AR4: =COUNTIF($F4:$AJ4,"LA") -> 0 | AS4: =SUM(AO4:AR4) -> 0
A5: ContratadO | B5: Canaglia Carreira, Patricia | C5: 28460124 | D5: Zapiola 2457 - Castelar | E5: 11-3158-9949 | F5: P | G5: P | H5: P | L5: P | M5: P | N5: P | O5: FA | R5: P | S5: P | T5: P | Y5: P | Z5: LM | AA5: LM | AD5: LM | AE5: LM | AF5: LM | AJ5: P | AM5: =IFS(AN5>3,"NO CORRESPONDE FRANCO",AS5>0,"NO CORRESPONDE FRANCO",AS5=0,"") -> NO CORRESPONDE FRANCO | AN5: =COUNTIF($F5:$AJ5,"LLT") -> 0 | AO5: =COUNTIF($F5:$AJ5,"LM") -> 5 | AP5: =COUNTIF($F5:$AJ5,"FaC") -> 0 | AQ5: =COUNTIF($F5:$AJ5,"LxE") -> 0 | AR5: =COUNTIF($F5:$AJ5,"LA") -> 0 | AS5: =SUM(AO5:AR5) -> 5
A6: Contratado | B6: Frias, Silvia Gabriela | C6: 25980677 | D6: Beruti 2190-Merlo | E6: 2204716048 | F6: P | G6: P | H6: LLT | L6: LLT | M6: P | N6: LLT | O6: LLT | R6: P | S6: P | T6: P | X6: P | Y6: P | Z6: P | AA6: P | AD6: P | AE6: P | AF6: P | AJ6: P | AM6: =IFS(AN6>3,"NO CORRESPONDE FRANCO",AS6>0,"NO CORRESPONDE FRANCO",AS6=0,"") -> NO CORRESPONDE FRANCO | AN6: =COUNTIF($F6:$AJ6,"LLT") -> 4 | AO6: =COUNTIF($F6:$AJ6,"LM") -> 0 | AP6: =COUNTIF($F6:$AJ6,"FaC") -> 0 | AQ6: =COUNTIF($F6:$AJ6,"LxE") -> 0 | AR6: =COUNTIF($F6:$AJ6,"LA") -> 0 | AS6: =SUM(AO6:AR6) -> 0
A7: Contratado | B7: Gomez Santiago | C7: 45012085 | D7: Asamblea 1727- P.CHACABUCO- CABA | E7: 11-2164-4882 | F7: LLT | G7: P | H7: LLT | L7: LLT | M7: LLT | N7: LLT | O7: LLT | R7: LLT | S7: LLT | T7: LLT | X7: LLT | Y7: LM | Z7: LLT | AA7: LLT | AD7: LLT | AE7: LLT | AF7: LLT | AJ7: P | AM7: =IFS(AN7>3,"NO CORRESPONDE FRANCO",AS7>0,"NO CORRESPONDE FRANCO",AS7=0,"") -> NO CORRESPONDE FRANCO | AN7: =COUNTIF($F7:$AJ7,"LLT") -> 15 | AO7: =COUNTIF($F7:$AJ7,"LM") -> 1 | AP7: =COUNTIF($F7:$AJ7,"FaC") -> 0 | AQ7: =COUNTIF($F7:$AJ7,"LxE") -> 0 | AR7: =COUNTIF($F7:$AJ7,"LA") -> 0 | AS7: =SUM(AO7:AR7) -> 1
A8: Contratado | B8: Farias, Nahuel | C8: 44884266 | D8: Angel Gallardo 3880 - Jose C Paz | E8: 11-2358-7333 | F8: P | G8: P | H8: LLT | L8: P | M8: CG | N8: LLT | O8: P | Q8: P | R8: P | S8: P | T8: P | V8: P | X8: P | Y8: LLT | Z8: P | AD8: P | AE8: P | AF8: LLT | AJ8: CG | AM8: =IFS(AN8>3,"NO CORRESPONDE FRANCO",AS8>0,"NO CORRESPONDE FRANCO",AS8=0,"") -> NO CORRESPONDE FRANCO | AN8: =COUNTIF($F8:$AJ8,"LLT") -> 4 | AO8: =COUNTIF($F8:$AJ8,"LM") -> 0 | AP8: =COUNTIF($F8:$AJ8,"FaC") -> 0 | AQ8: =COUNTIF($F8:$AJ8,"LxE") -> 0 | AR8: =COUNTIF($F8:$AJ8,"LA") -> 0 | AS8: =SUM(AO8:AR8) -> 0
A9: Contratado | B9: Caceres, Antonela | C9: 34999122 | D9: COSQUIN 2452 - CABA | E9: 11-3159-9509 | F9: P | G9: P | H9: P | L9: LLT | M9: P | N9: P | O9: P | R9: P | S9: LLT | T9: P | X9: FA | Y9: LLT | Z9: P | AA9: P | AD9: P | AE9: P | AF9: P | AJ9: P | AM9: =IFS(AN9>3,"NO CORRESPONDE FRANCO",AS9>0,"NO CORRESPONDE FRANCO",AS9=0,"") | AN9: =COUNTIF($F9:$AJ9,"LLT") -> 3 | AO9: =COUNTIF($F9:$AJ9,"LM") -> 0 | AP9: =COUNTIF($F9:$AJ9,"FaC") -> 0 | AQ9: =COUNTIF($F9:$AJ9,"LxE") -> 0 | AR9: =COUNTIF($F9:$AJ9,"LA") -> 0 | AS9: =SUM(AO9:AR9) -> 0
A10: Contratado | B10: Ferreira Erik Nehuen | C10: 46201746 | D10: Agustin Magaldi 3555 - Hurlingam | E10: 11-7063-3014 | F10: LLT | G10: P | H10: P | L10: LA | M10: LA | N10: LA | O10: LA | P10: LA | Q10: LA | R10: LA | S10: FA | T10: CG | X10: LLT | Y10: P | Z10: P | AA10: P | AD10: P | AE10: P | AF10: LLT | AJ10: P | AM10: =IFS(AN10>3,"NO CORRESPONDE FRANCO",AS10>0,"NO CORRESPONDE FRANCO",AS10=0,"") -> NO CORRESPONDE FRANCO | AN10: =COUNTIF($F10:$AJ10,"LLT") -> 3 | AO10: =COUNTIF($F10:$AJ10,"LM") -> 0 | AP10: =COUNTIF($F10:$AJ10,"FaC") -> 0 | AQ10: =COUNTIF($F10:$AJ10,"LxE") -> 0 | AR10: =COUNTIF($F10:$AJ10,"LA") -> 7 | AS10: =SUM(AO10:AR10) -> 7
A11: Contratado | B11: Rejala Efrain Juan Carlos | C11: 44101107 | D11: Calle 888 Altura 2016- Solano | E11: 11-76154808 | F11: LA | G11: LA | H11: P | L11: P | M11: P | N11: P | O11: P | R11: P | S11: P | T11: P | X11: P | Y11: LLT | Z11: P | AA11: LLT | AD11: CG | AE11: P | AF11: LLT | AH11: LLT | AJ11: P | AM11: =IFS(AN11>3,"NO CORRESPONDE FRANCO",AS11>0,"NO CORRESPONDE FRANCO",AS11=0,"") -> NO CORRESPONDE FRANCO | AN11: =COUNTIF($F11:$AJ11,"LLT") -> 4 | AO11: =COUNTIF($F11:$AJ11,"LM") -> 0 | AP11: =COUNTIF($F11:$AJ11,"FaC") -> 0 | AQ11: =COUNTIF($F11:$AJ11,"LxE") -> 0 | AR11: =COUNTIF($F11:$AJ11,"LA") -> 2 | AS11: =SUM(AO11:AR11) -> 2
A12: Contratado | B12: Gauna Sebastian Rodrigo | C12: 44052040 | D12: Pablo Podesta 450 - Temperley | E12: 11-5332-5279 | F12: LLT | G12: P | H12: P | L12: P | M12: LLT | N12: P | O12: LM | R12: LM | S12: LM | T12: P | X12: LLT | Y12: LLT | Z12: P | AA12: LLT | AD12: LLT | AE12: LLT | AF12: LM | AJ12: p | AK12: =VLOOKUP(AJ12,DATOS!$A:$B,2,0) -> #REF! | AM12: =IFS(AN12>3,"NO CORRESPONDE FRANCO",AS12>0,"NO CORRESPONDE FRANCO",AS12=0,"") -> NO CORRESPONDE FRANCO | AN12: =COUNTIF($F12:$AJ12,"LLT") -> 7 | AO12: =COUNTIF($F12:$AJ12,"LM") -> 4 | AP12: =COUNTIF($F12:$AJ12,"FaC") -> 0 | AQ12: =COUNTIF($F12:$AJ12,"LxE") -> 0 | AR12: =COUNTIF($F12:$AJ12,"LA") -> 0 | AS12: =SUM(AO12:AR12) -> 4
A13: Contratado | B13: Obispo, Valeria Soledad | C13: 32359059 | D13: Juncal 2514, 8º Porteria- Recoleta- CABA | E13: 11-3569-6039 | F13: P | G13: P | H13: P | L13: P | M13: P | N13: P | O13: P | R13: P | S13: P | T13: CG | U13: P | X13: LLT | Y13: P | Z13: LA | AA13: LA | AD13: FA | AE13: P | AF13: P | AJ13: P | AM13: =IFS(AN13>3,"NO CORRESPONDE FRANCO",AS13>0,"NO CORRESPONDE FRANCO",AS13=0,"") -> NO CORRESPONDE FRANCO | AN13: =COUNTIF($F13:$AJ13,"LLT") -> 1 | AO13: =COUNTIF($F13:$AJ13,"LM") -> 0 | AP13: =COUNTIF($F13:$AJ13,"FaC") -> 0 | AQ13: =COUNTIF($F13:$AJ13,"LxE") -> 0 | AR13: =COUNTIF($F13:$AJ13,"LA") -> 2 | AS13: =SUM(AO13:AR13) -> 2
A14: Contratado | B14: Leon Florencia | C14: 37019337 | D14: Carlos Perette 530 - CABA | E14: 11-6185-8434 | F14: LLT | G14: P | H14: P | L14: P | M14: P | N14: P | O14: P | R14: P | S14: P | T14: P | X14: P | Y14: P | Z14: P | AA14: FA | AD14: P | AE14: P | AF14: P | AJ14: P | AM14: =IFS(AN14>3,"NO CORRESPONDE FRANCO",AS14>0,"NO CORRESPONDE FRANCO",AS14=0,"") | AN14: =COUNTIF($F14:$AJ14,"LLT") -> 1 | AO14: =COUNTIF($F14:$AJ14,"LM") -> 0 | AP14: =COUNTIF($F14:$AJ14,"FaC") -> 0 | AQ14: =COUNTIF($F14:$AJ14,"LxE") -> 0 | AR14: =COUNTIF($F14:$AJ14,"LA") -> 0 | AS14: =SUM(AO14:AR14) -> 0
A16: GRUPO "B" TT - 14 A 22 HS | F16: 1 | G16: 2 | H16: 3 | I16: 4 | J16: 5 | K16: 6 | L16: 7 | M16: 8 | N16: 9 | O16: 10 | P16: 11 | Q16: 12 | R16: 13 | S16: 14 | T16: 15 | U16: 16 | V16: 17 | W16: 18 | X16: 19 | Y16: 20 | Z16: 21 | AA16: 22 | AB16: 23 | AC16: 24 | AD16: 25 | AE16: 26 | AF16: 27 | AG16: 28 | AH16: 29 | AI16: 30 | AJ16: 31
A17: JERARQUIA | B17: NOMBRE Y APELLIDO | C17: LP/DNI | D17: DOMICILIO | E17: CELULAR | F17: S | G17: D | H17: L | I17: M | J17: M | K17: J | L17: V | M17: S | N17: D | O17: L | P17: M | Q17: M | R17: J | S17: V | T17: S | U17: D | V17: L | W17: M | X17: M | Y17: J | Z17: V | AA17: S | AB17: D | AC17: L | AD17: M | AE17: M | AF17: J | AG17: V | AH17: S | AI17: D | AJ17: L
A18: Contratado | B18: Gonzalez, Monica | C18: 18224482 | D18: Fonrouge 44 Piso 1 Dpto 4 - Liniers | E18: 11-6192-2899 | F18: P | G18: P | H18: P | I18: P | J18: P | M18: P | N18: P | O18: P | R18: P | S18: P | T18: P | U18: P | Y18: P | Z18: P | AA18: P | AB18: P | AD18: P | AE18: P | AF18: P | AG18: CG | AM18: =IFS(AN18>3,"NO CORRESPONDE FRANCO",AS18>0,"NO CORRESPONDE FRANCO",AS18=0,"") | AN18: =COUNTIF($F18:$AJ18,"LLT") -> 0 | AO18: =COUNTIF($F18:$AJ18,"LM") -> 0 | AP18: =COUNTIF($F18:$AJ18,"FaC") -> 0 | AQ18: =COUNTIF($F18:$AJ18,"LxE") -> 0 | AR18: =COUNTIF($F18:$AJ18,"LA") -> 0 | AS18: =SUM(AO18:AR18) -> 0
A19: Contratado | B19: Sanchez, Iona Victoria | C19: 46994265 | D19: Oyuela 1500 - Avellaneda | E19: 11-5895-8516 | F19: LLT | G19: LLT | H19: LLT | I19: LLT | M19: P | N19: LLT | O19: LLT | R19: LLT | S19: LLT | U19: P | Y19: LM | Z19: LM | AA19: LLT | AD19: LLT | AE19: P | AG19: LLT | AM19: =IFS(AN19>3,"NO CORRESPONDE FRANCO",AS19>0,"NO CORRESPONDE FRANCO",AS19=0,"") -> NO CORRESPONDE FRANCO | AN19: =COUNTIF($F19:$AJ19,"LLT") -> 11 | AO19: =COUNTIF($F19:$AJ19,"LM") -> 2 | AP19: =COUNTIF($F19:$AJ19,"FaC") -> 0 | AQ19: =COUNTIF($F19:$AJ19,"LxE") -> 0 | AR19: =COUNTIF($F19:$AJ19,"LA") -> 0 | AS19: =SUM(AO19:AR19) -> 2
A20: Contratado | B20: Torrez Hurtado, Nayra | C20: 46438246 | D20: Av. La Plata 1781 - CABA | E20: 11-5703-5949 | F20: LLT | G20: LLT | H20: LLT | I20: LLT | K20: PASA AL GRUPO 1 12*36 | AM20: =IFS(AN20>3,"NO CORRESPONDE FRANCO",AS20>0,"NO CORRESPONDE FRANCO",AS20=0,"") | AN20: =COUNTIF($F20:$AJ20,"LLT") -> 3 | AO20: =COUNTIF($F20:$AJ20,"LM") -> 0 | AP20: =COUNTIF($F20:$AJ20,"FaC") -> 0 | AQ20: =COUNTIF($F20:$AJ20,"LxE") -> 0 | AR20: =COUNTIF($F20:$AJ20,"LA") -> 0 | AS20: =SUM(AO20:AR20) -> 0
A21: Contratado | B21: Pintado, Santiago | C21: 43404637 | D21: Castro Barros 10 | E21: 11-3161-2269 | F21: P | G21: P | H21: P | I21: P | M21: P | N21: P | O21: P | R21: P | S21: P | T21: P | U21: FA | Y21: P | Z21: P | AA21: P | AD21: P | AE21: P | AF21: P | AG21: FA | AM21: =IFS(AN21>3,"NO CORRESPONDE FRANCO",AS21>0,"NO CORRESPONDE FRANCO",AS21=0,"") | AN21: =COUNTIF($F21:$AJ21,"LLT") -> 0 | AO21: =COUNTIF($F21:$AJ21,"LM") -> 0 | AP21: =COUNTIF($F21:$AJ21,"FaC") -> 0 | AQ21: =COUNTIF($F21:$AJ21,"LxE") -> 0 | AR21: =COUNTIF($F21:$AJ21,"LA") -> 0 | AS21: =SUM(AO21:AR21) -> 0
A22: Contratado | B22: Castillo, Gisell | C22: 36405101 | D22: AV. RAMON CASTILLO 1500 - CABA | E22: 11-2720-6641 | F22: LLT | G22: LLT | H22: P | I22: P | M22: P | N22: FA | O22: P | R22: P | S22: LLT | T22: P | U22: P | Y22: P | Z22: P | AA22: P | AD22: P | AE22: P | AF22: P | AG22: LLT | AM22: =IFS(AN22>3,"NO CORRESPONDE FRANCO",AS22>0,"NO CORRESPONDE FRANCO",AS22=0,"") -> NO CORRESPONDE FRANCO | AN22: =COUNTIF($F22:$AJ22,"LLT") -> 4 | AO22: =COUNTIF($F22:$AJ22,"LM") -> 0 | AP22: =COUNTIF($F22:$AJ22,"FaC") -> 0 | AQ22: =COUNTIF($F22:$AJ22,"LxE") -> 0 | AR22: =COUNTIF($F22:$AJ22,"LA") -> 0 | AS22: =SUM(AO22:AR22) -> 0
A23: Contratado | B23: De Sarro Malena | C23: 44484026 | D23: Marco Avellaneda 1356 - Remios de Escalada Lanus | E23: 11-6449-9599 | F23: P | G23: P | H23: P | I23: P | L23: LA | M23: LA | N23: LA | O23: LA | P23: LA | Q23: LA | R23: LA | S23: P | T23: P | U23: P | Y23: P | Z23: P | AA23: FA | AD23: P | AE23: P | AF23: P | AG23: P | AM23: =IFS(AN23>3,"NO CORRESPONDE FRANCO",AS23>0,"NO CORRESPONDE FRANCO",AS23=0,"") -> NO CORRESPONDE FRANCO | AN23: =COUNTIF($F23:$AJ23,"LLT") -> 0 | AO23: =COUNTIF($F23:$AJ23,"LM") -> 0 | AP23: =COUNTIF($F23:$AJ23,"FaC") -> 0 | AQ23: =COUNTIF($F23:$AJ23,"LxE") -> 0 | AR23: =COUNTIF($F23:$AJ23,"LA") -> 7 | AS23: =SUM(AO23:AR23) -> 7
A24: Contratado | B24: Yaskulowski. Silvia Daniela | C24: 25413482 | D24: Villegas 81-el palomar | E24: 11-2450-1351 | F24: P | G24: P | H24: P | I24: P | L24: P | M24: P | N24: P | O24: P | R24: P | S24: P | T24: CG | U24: FA | Y24: P | Z24: P | AA24: P | AD24: LA | AE24: LA | AF24: LA | AG24: LA | AH24: LA | AI24: LA
A25: Contratado | B25: Gonzalez Michel, Martina Gala | C25: 36359202 | D25: Pedernera 494 Flores CABA | E25: 11-3705-5122 | F25: P | G25: P | H25: P | I25: LLT | M25: LLT | N25: LLT | O25: LLT | R25: LLT | S25: P | T25: LLT | U25: LLT | Y25: LLT | Z25: LLT | AA25: LLT | AD25: LLT | AE25: LLT | AF25: LLT | AG25: LLT | AI25: P | AM25: =IFS(AN25>3,"NO CORRESPONDE FRANCO",AS25>0,"NO CORRESPONDE FRANCO",AS25=0,"") -> NO CORRESPONDE FRANCO | AN25: =COUNTIF($F25:$AJ25,"LLT") -> 14 | AO25: =COUNTIF($F25:$AJ25,"LM") -> 0 | AP25: =COUNTIF($F25:$AJ25,"FaC") -> 0 | AQ25: =COUNTIF($F25:$AJ25,"LxE") -> 0 | AR25: =COUNTIF($F25:$AJ25,"LA") -> 0 | AS25: =SUM(AO25:AR25) -> 0
A26: Contratado | B26: Romero, Karina Giselle | C26: 39416059 | D26: Gualeguaychu 1830 - PSIO 7 DTO A - MONTE CASTRO | E26: 11-6453-1164 | F26: LLT | G26: P | H26: P | I26: P | M26: P | N26: LLT | O26: P | R26: LLT | S26: P | T26: P | U26: P | Y26: P | Z26: P | AA26: CG | AD26: P | AE26: P | AF26: P | AG26: P | AH26: LM | AM26: =IFS(AN26>3,"NO CORRESPONDE FRANCO",AS26>0,"NO CORRESPONDE FRANCO",AS26=0,"") -> NO CORRESPONDE FRANCO | AN26: =COUNTIF($F26:$AJ26,"LLT") -> 3 | AO26: =COUNTIF($F26:$AJ26,"LM") -> 1 | AP26: =COUNTIF($F26:$AJ26,"FaC") -> 0 | AQ26: =COUNTIF($F26:$AJ26,"LxE") -> 0 | AR26: =COUNTIF($F26:$AJ26,"LA") -> 0 | AS26: =SUM(AO26:AR26) -> 1
A27: Contratado | B27: Cordoba Romina | C27: 33669832 | D27: Sanchez 2227 PH 3- CABA | E27: 11-4938-6278 | F27: P | G27: P | H27: P | I27: P | M27: P | N27: P | O27: P | R27: FA | S27: P | T27: P | U27: P | Y27: P | Z27: P | AA27: P | AD27: P | AE27: P | AF27: P | AG27: P | AM27: =IFS(AN27>3,"NO CORRESPONDE FRANCO",AS27>0,"NO CORRESPONDE FRANCO",AS27=0,"") | AN27: =COUNTIF($F27:$AJ27,"LLT") -> 0 | AO27: =COUNTIF($F27:$AJ27,"LM") -> 0 | AP27: =COUNTIF($F27:$AJ27,"FaC") -> 0 | AQ27: =COUNTIF($F27:$AJ27,"LxE") -> 0 | AR27: =COUNTIF($F27:$AJ27,"LA") -> 0 | AS27: =SUM(AO27:AR27) -> 0
A28: Contratado | B28: Condori Leonel | C28: 46991061 | D28: Av 25 de Mayo 3124-Lanus Oeste | E28: 11-22793480 | F28: P | G28: P | H28: P | I28: P | K28: P | M28: P | N28: P | O28: P | R28: P | S28: P | T28: P | U28: P | W28: LA | X28: LA | Y28: LA | Z28: LA | AA28: LA | AB28: LA | AD28: FA | AE28: FA | AF28: CG | AG28: P | AM28: =IFS(AN28>3,"NO CORRESPONDE FRANCO",AS28>0,"NO CORRESPONDE FRANCO",AS28=0,"") -> NO CORRESPONDE FRANCO | AN28: =COUNTIF($F28:$AJ28,"LLT") -> 0 | AO28: =COUNTIF($F28:$AJ28,"LM") -> 0 | AP28: =COUNTIF($F28:$AJ28,"FaC") -> 0 | AQ28: =COUNTIF($F28:$AJ28,"LxE") -> 0 | AR28: =COUNTIF($F28:$AJ28,"LA") -> 6 | AS28: =SUM(AO28:AR28) -> 6
A29: Contratado | B29: Franco Laura | C29: 26786100 | D29: Alberti 1829 Planta Baja Dto. B - Parque Patricios | E29: 11-5490-2874 | W29: P | Y29: P | Z29: p | AE29: P | AF29: P | AG29: P
A30: GRUPO "C" TT - 14 A 22 HS | F30: 1 | G30: 2 | H30: 3 | I30: 4 | J30: 5 | K30: 6 | L30: 7 | M30: 8 | N30: 9 | O30: 10 | P30: 11 | Q30: 12 | R30: 13 | S30: 14 | T30: 15 | U30: 16 | V30: 17 | W30: 18 | X30: 19 | Y30: 20 | Z30: 21 | AA30: 22 | AB30: 23 | AC30: 24 | AD30: 25 | AE30: 26 | AF30: 27 | AG30: 28 | AH30: 29 | AI30: 30 | AJ30: 31
A31: JERARQUIA | B31: NOMBRE Y APELLIDO | C31: LP/DNI | D31: DOMICILIO | E31: CELULAR | F31: S | G31: D | H31: L | I31: M | J31: M | K31: J | L31: V | M31: S | N31: D | O31: L | P31: M | Q31: M | R31: J | S31: V | T31: S | U31: D | V31: L | W31: M | X31: M | Y31: J | Z31: V | AA31: S | AB31: D | AC31: L | AD31: M | AE31: M | AF31: J | AG31: V | AH31: S | AI31: D | AJ31: L
A32: Contratado | B32: Garófalo, Oscar Ezequiel | C32: 37181824 | D32: Colombres 1565- Boedo | E32: 11-6371-0494 | I32: P | J32: P | K32: P | N32: P | O32: P | P32: P | Q32: P | U32: P | V32: P | W32: P | Z32: P | AA32: P | AB32: P | AC32: P | AG32: P | AI32: P | AM32: =IFS(AN32>3,"NO CORRESPONDE FRANCO",AS32>0,"NO CORRESPONDE FRANCO",AS32=0,"") | AN32: =COUNTIF($F32:$AJ32,"LLT") -> 0 | AO32: =COUNTIF($F32:$AJ32,"LM") -> 0 | AP32: =COUNTIF($F32:$AJ32,"FaC") -> 0 | AQ32: =COUNTIF($F32:$AJ32,"LxE") -> 0 | AR32: =COUNTIF($F32:$AJ32,"LA") -> 0 | AS32: =SUM(AO32:AR32) -> 0
A33: Contratado | B33: Delvecchio, Diana Gabriela | C33: 22508743 | D33: MAIPU 367- MORENO | E33: 11-2544-4664 | J33: LM | K33: LM | L33: LM | M33: LM | N33: LM | O33: LM | P33: LM | Q33: FA | U33: P | V33: p | W33: P | Z33: LM | AA33: LLT | AC33: LM | AD33: LM | AG33: P | AH33: P | AI33: P | AK33: 13 A 21HS AUTORIZADO POR SUB JOVANOVICH | AM33: =IFS(AN33>3,"NO CORRESPONDE FRANCO",AS33>0,"NO CORRESPONDE FRANCO",AS33=0,"") -> NO CORRESPONDE FRANCO | AN33: =COUNTIF($F33:$AJ33,"LLT") -> 1 | AO33: =COUNTIF($F33:$AJ33,"LM") -> 10 | AP33: =COUNTIF($F33:$AJ33,"FaC") -> 0 | AQ33: =COUNTIF($F33:$AJ33,"LxE") -> 0 | AR33: =COUNTIF($F33:$AJ33,"LA") -> 0 | AS33: =SUM(AO33:AR33) -> 10
A34: Contratado | B34: Herrera German Hernando | C34: 41898021 | D34: Saenz Peña 1750 - Merlo | E34: 11-3252-6607 | I34: LLT | J34: LLT | K34: LLT | N34: P | O34: LM | P34: LLT | Q34: LLT | U34: P | V34: P | W34: P | Z34: LLT | AA34: LLT | AB34: LLT | AC34: LM | AG34: LTT | AH34: LLT | AI34: P | AM34: =IFS(AN34>3,"NO CORRESPONDE FRANCO",AS34>0,"NO CORRESPONDE FRANCO",AS34=0,"") -> NO CORRESPONDE FRANCO | AN34: =COUNTIF($F34:$AJ34,"LLT") -> 9 | AO34: =COUNTIF($F34:$AJ34,"LM") -> 2 | AP34: =COUNTIF($F34:$AJ34,"FaC") -> 0 | AQ34: =COUNTIF($F34:$AJ34,"LxE") -> 0 | AR34: =COUNTIF($F34:$AJ34,"LA") -> 0 | AS34: =SUM(AO34:AR34) -> 2
A35: Contratado | B35: Gabriel, Mejia | C35: 42157414 | D35: calle 850 n°2502 solano PBA | E35: 11-59898773 | I35: P | J35: P | K35: P | M35: P | N35: P | O35: P | P35: P | Q35: CG | U35: P | V35: P | W35: P | Z35: P | AA35: P | AB35: LLT | AC35: P | AG35: P | AH35: P | AI35: LLT | AM35: =IFS(AN35>3,"NO CORRESPONDE FRANCO",AS35>0,"NO CORRESPONDE FRANCO",AS35=0,"") | AN35: =COUNTIF($F35:$AJ35,"LLT") -> 2 | AO35: =COUNTIF($F35:$AJ35,"LM") -> 0 | AP35: =COUNTIF($F35:$AJ35,"FaC") -> 0 | AQ35: =COUNTIF($F35:$AJ35,"LxE") -> 0 | AR35: =COUNTIF($F35:$AJ35,"LA") -> 0 | AS35: =SUM(AO35:AR35) -> 0
A36: Contratado | B36: Castillo Barrios, Edgard David | C36: 30081588 | D36: Tarija 3753- Boedo | E36: 11-5696-7489 | I36: LA | J36: LA | K36: LA | L36: LA | M36: LA | N36: LA | O36: P | P36: P | Q36: P | U36: P | V36: P | W36: P | Z36: P | AA36: P | AB36: LLT | AC36: P | AG36: P | AH36: P | AI36: FA | AM36: =IFS(AN36>3,"NO CORRESPONDE FRANCO",AS36>0,"NO CORRESPONDE FRANCO",AS36=0,"") -> NO CORRESPONDE FRANCO | AN36: =COUNTIF($F36:$AJ36,"LLT") -> 1 | AO36: =COUNTIF($F36:$AJ36,"LM") -> 0 | AP36: =COUNTIF($F36:$AJ36,"FaC") -> 0 | AQ36: =COUNTIF($F36:$AJ36,"LxE") -> 0 | AR36: =COUNTIF($F36:$AJ36,"LA") -> 6 | AS36: =SUM(AO36:AR36) -> 6
A37: Contratado | B37: Rojas Paula | C37: 21764781 | D37: Plaza 2544 4C - caba | E37: 11-5337-2495 | I37: LA | J37: LA | K37: LA | L37: LA | M37: LA | N37: LA | O37: LA | Q37: P | U37: P | V37: P | W37: P | Z37: P | AA37: P | AB37: P | AC37: P | AG37: P | AH37: P | AI37: FA | AM37: =IFS(AN37>3,"NO CORRESPONDE FRANCO",AS37>0,"NO CORRESPONDE FRANCO",AS37=0,"") -> NO CORRESPONDE FRANCO | AN37: =COUNTIF($F37:$AJ37,"LLT") -> 0 | AO37: =COUNTIF($F37:$AJ37,"LM") -> 0 | AP37: =COUNTIF($F37:$AJ37,"FaC") -> 0 | AQ37: =COUNTIF($F37:$AJ37,"LxE") -> 0 | AR37: =COUNTIF($F37:$AJ37,"LA") -> 7 | AS37: =SUM(AO37:AR37) -> 7
A38: Contratado | B38: Boned, Sebastian Leonel | C38: 40258358 | D38: 9 de Julio 5426 Billinghurts PH - dpto 1 | E38: 11-4166-2048 | I38: LLT | J38: P | K38: LLT | N38: LLT | O38: P | P38: LLT | Q38: P | U38: LM | V38: P | W38: P | Z38: P | AA38: LLT | AB38: P | AC38: LLT | AG38: P | AH38: LM | AI38: LLT | AM38: =IFS(AN38>3,"NO CORRESPONDE FRANCO",AS38>0,"NO CORRESPONDE FRANCO",AS38=0,"") -> NO CORRESPONDE FRANCO | AN38: =COUNTIF($F38:$AJ38,"LLT") -> 7 | AO38: =COUNTIF($F38:$AJ38,"LM") -> 2 | AP38: =COUNTIF($F38:$AJ38,"FaC") -> 0 | AQ38: =COUNTIF($F38:$AJ38,"LxE") -> 0 | AR38: =COUNTIF($F38:$AJ38,"LA") -> 0 | AS38: =SUM(AO38:AR38) -> 2
A39: Contratado | B39: Valentina Guzmán | C39: 47202075 | D39: La Rioja 2212 - Quilmes Oeste | E39: 11-2835-6374 | I39: P | J39: P | K39: P | N39: P | O39: FA | P39: P | Q39: LLT | U39: P | V39: P | W39: LA | X39: LA | Y39: LA | Z39: LA | AA39: LA | AB39: LA | AG39: P | AH39: P | AI39: CG | AM39: =IFS(AN39>3,"NO CORRESPONDE FRANCO",AS39>0,"NO CORRESPONDE FRANCO",AS39=0,"") -> NO CORRESPONDE FRANCO | AN39: =COUNTIF($F39:$AJ39,"LLT") -> 1 | AO39: =COUNTIF($F39:$AJ39,"LM") -> 0 | AP39: =COUNTIF($F39:$AJ39,"FaC") -> 0 | AQ39: =COUNTIF($F39:$AJ39,"LxE") -> 0 | AR39: =COUNTIF($F39:$AJ39,"LA") -> 6 | AS39: =SUM(AO39:AR39) -> 6
